Workbook
Name Full_Print: #REF!
Name Full_Print: #REF!
Name Interest_Rate: #REF!
Name Interest_Rate: #REF!
Name Loan_Amount: #REF!
Name Loan_Amount: #REF!
Name Loan_Start: #REF!
Name Loan_Start: #REF!
Name Loan_Years: #REF!
Name Loan_Years: #REF!
Name Number_of_Payments: #REF!
Name Number_of_Payments: #REF!
Name Total_Cost: #REF!
Name Total_Cost: #REF!
Name Total_Interest: #REF!
Name Total_Interest: #REF!

Sheet Requerimientos
A1: REQUERIMIENTOS DE INFORMACIÓN PARA TRABAJAR LA HOJA EXCEL
A4: No | B4: Datos | C4: Fuente | D4: Observación | E4: Hoja Excel | F4: Alimenta
A5: 1 | B5: Unidades a vender por año | C5: PMercadeo | D5: Punto de Cuota de mercado a 5 años | E5: Supuestos de Ventas y Costos | F5: Estado Resultado, Punto Equilibrio, Razones Financieras.
A6: =A5+1 -> 2 | B6: Precio de Venta sin IVA | C6: PMercadeo | D6: Precio de Venta de 5 años | E6: Supuestos de Ventas y Costos | F6: Estado Resultado, Punto Equilibrio, Razones Financieras.
A7: =A6+1 -> 3 | B7: Estimaciones de Ventas | C7: PMercadeo | D7: La Hoja excel lo hace para cada línea y da el total por año en supuestos de ventas y costos; posteriormente alimenta en Efinancieros al Estado de Resultado las ventas. | E7: Supuestos de Ventas y Costos | F7: Estado Resultado, Punto Equilibrio, Razones Financieras.
A8: =A7+1 -> 4 | B8: Presupuesto de Mercadeo | C8: PMercadeo | D8: Presupuesto de Mercadeo, es una cuenta de Gastos Generales. | E8: Supuestos de Ventas y Costos | F8: Estado Resultado, Punto Equilibrio.
A9: =A8+1 -> 5 | B9: Activos Fijos x Linea | C9: Pproducción | D9: Lista de Activos Fijos (Terrenos, Edificio, Maquinaria, Herramientas, Mobiliario de Oficina, Equipo Cómputo, Equipo Reparto, Otros. | E9: Supuestos de Inversión | F9: VAN, TIR, Relacion Beneficio Costo, Razones Financieras, Balance General, Flujo de Caja
A10: =A9+1 -> 6 | B10: Depreciación Activos Fijos x Línea | C10: Pproducción | D10: Depreciación Activos (Ley Equidad Fiscal) | E10: Supuestos de Inversión | F10: Supuestos Ventas, precisamente los Gastos Generales, VAN, TIR, Punto Equilibrio, B General.
A11: =A10+1 -> 7 | B11: Mantenimiento y reparación Activos | C11: Pproducción | D11: Va al Gasto General | E11: Supuestos de Ventas y Costos | F11: Gasto General.
A12: =A11+1 -> 8 | B12: Alquiler | C12: Pproducción | D12: Va al Gasto General | E12: Supuestos de Ventas y Costos | F12: Gasto General.
A13: =A12+1 -> 9 | B13: Permisos y licencias | C13: Pproducción | D13: Va al Gasto General | E13: Supuestos de Ventas y Costos | F13: Gasto General.
A14: =A13+1 -> 10 | B14: Renovación activos | C14: Pproducción | D14: Va al Gasto General | E14: Supuestos de Ventas y Costos | F14: Gasto General.
A15: =A14+1 -> 11 | B15: Demas Gastos Generales | C15: Pproducción | D15: Va al Gasto General | E15: Supuestos de Ventas y Costos | F15: Gasto General.
A16: =A15+1 -> 12 | B16: Cargos, número de colaboradores y su salario mensual, más la proyección de incremento durante 5 años | C16: Pproducción | D16: Calculo Mano de Obra Anual con Prestaciones | E16: SALARIOS | F16: Supuestos de Ventas y Costos
A17: =A16+1 -> 13 | B17: Material Directo x Unidad de Venta | C17: Pproducción | D17: Estimar Mdirecto e Indirecto por cada unidad de venta, para calcular el costo de venta por línea y el costo de venta anual que pasa al ER | E17: Supuestos de Ventas y Costos | F17: Estado Resultado, Punto Equilibrio, Razones Financieras.
... A19: =A18+1 -> 15 | B19: Definir el capital de trabajo | C19: PFinanzas | D19: La hoja excel estima los costos y gastos del primer mes de operación que son efectivos (Suma Costo de Venta + Mano de Obra+ Gastos Generales) | E19: Supuestos de Inversión | F19: Inversión Total

Sheet Salarios
B1: Crecimiento Anual: | C1: 0.06
A3: Mano de OBRA DIRECTA | B3: Año 1 / Mes | D3: Año 2 / Mes | F3: Año 3 / Mes | H3: Año 4 / Mes | J3: Año 5 / Mes
B4: Cant | C4: Salario | D4: Cant | E4: Salario | F4: Cant | G4: Salario | H4: Cant | I4: Salario | J4: Cant | K4: Salario
A5: Director e Ingeniero Full-Stack | B5: 1 | C5: 15000 | D5: 1 | E5: =+C5*(1+$C$1) -> 15900 | F5: 1 | G5: =+E5*(1+$C$1) -> 16854 | H5: 1 | I5: =+G5*(1+$C$1) -> 17865.24 | J5: 1 | K5: =+I5*(1+$C$1) -> 18937.154
D6: 1 | E6: =+C6*(1+$C$1) -> 0 | F6: 1 | G6: =+E6*(1+$C$1) -> 0 | H6: 1 | I6: =+G6*(1+$C$1) -> 0 | J6: 1 | K6: =+I6*(1+$C$1) -> 0
D8: =+B8 -> 0 | E8: =+C8*(1+$C$1) -> 0 | F8: =+D8 -> 0 | G8: =+E8*(1+$C$1) -> 0 | H8: =+F8 -> 0 | I8: =+G8*(1+$C$1) -> 0 | J8: =+H8 -> 0 | K8: =+I8*(1+$C$1) -> 0
D9: =+B9 -> 0 | E9: =+C9*(1+$C$1) -> 0 | F9: =+D9 -> 0 | G9: =+E9*(1+$C$1) -> 0 | H9: =+F9 -> 0 | I9: =+G9*(1+$C$1) -> 0 | J9: =+H9 -> 0 | K9: =+I9*(1+$C$1) -> 0
D10: =+B10 -> 0 | E10: =+C10*(1+$C$1) -> 0 | F10: =+D10 -> 0 | G10: =+E10*(1+$C$1) -> 0 | H10: =+F10 -> 0 | I10: =+G10*(1+$C$1) -> 0 | J10: =+H10 -> 0 | K10: =+I10*(1+$C$1) -> 0
D11: =+B11 -> 0 | E11: =+C11*(1+$C$1) -> 0 | F11: =+D11 -> 0 | G11: =+E11*(1+$C$1) -> 0 | H11: =+F11 -> 0 | I11: =+G11*(1+$C$1) -> 0 | J11: =+H11 -> 0 | K11: =+I11*(1+$C$1) -> 0
D12: =+B12 -> 0 | E12: =+C12*(1+$C$1) -> 0 | F12: =+D12 -> 0 | G12: =+E12*(1+$C$1) -> 0 | H12: =+F12 -> 0 | I12: =+G12*(1+$C$1) -> 0 | J12: =+H12 -> 0 | K12: =+I12*(1+$C$1) -> 0
A13: Total | B13: =SUM(B5:B12) -> 1 | C13: =B5*C5+B6*C6+B9*C9+B8*C8+B10*C10+B11*C11+B12*C12 -> 15000 | D13: =D5+D6+D8+D9+D7+D10+D11+D12 -> 2 | E13: =D5*E5+D6*E6+D9*E9+D8*E8+D10*E10+D11*E11+D12*E12 -> 15900 | F13: =F5+F6+F9+F7+F8 -> 2 | G13: =F5*G5+F6*G6+F9*G9+F8*G8+F10*G10+F11*G11+F12*G12 -> 16854 | H13: =H9+H8+H7+H6+H5 -> 2 | I13: =H5*I5+H6*I6+H9*I9+H8*I8+H10*I10+H11*I11+H12*I12 -> 17865.24 | J13: =J5+J6+J7+J8+J9 -> 2 | K13: =J5*K5+J6*K6+J9*K9+J8*K8+J10*K10+J11*K11+J12*K12 -> 18937.154
A14: Total por año | B14: =C13*12 -> 180000 | D14: =E13*12 -> 190800 | F14: =G13*12 -> 202248 | H14: =I13*12 -> 214382.88 | J14: =K13*12 -> 227245.85
A15: Fuente: Elaboracion propia
A18: Mano de OBRA INDIRECTA | B18: Año 1 / Mes | D18: Año 2 / Mes | F18: Año 3 / Mes | H18: Año 4 / Mes | J18: Año 5 / Mes
B19: Cant | C19: Salario | D19: Cant | E19: Salario | F19: Cant | G19: Salario | H19: Cant | I19: Salario | J19: Cant | K19: Salario
D20: 1 | E20: 380.26 | F20: 1 | G20: 399.27 | H20: 1 | I20: 419.23 | J20: 1 | K20: 440.19
D21: 1 | E21: =+C21*(1+$C$1) -> 0 | F21: 1 | G21: =+E21*(1+$C$1) -> 0 | H21: 1 | I21: =+G21*(1+$C$1) -> 0 | J21: 1 | K21: =+I21*(1+$C$1) -> 0
D22: 1 | E22: =+C22*(1+$C$1) -> 0 | F22: 1 | G22: =+E22*(1+$C$1) -> 0 | H22: 1 | I22: =+G22*(1+$C$1) -> 0 | J22: 1 | K22: =+I22*(1+$C$1) -> 0
E23: =+C23*(1+$C$1) -> 0 | F23: 1 | G23: =+E23*(1+$C$1) -> 0 | H23: 1 | I23: =+G23*(1+$C$1) -> 0 | J23: 1 | K23: =+I23*(1+$C$1) -> 0
E24: =+C24*(1+$C$1) -> 0 | G24: =+E24*(1+$C$1) -> 0 | I24: =+G24*(1+$C$1) -> 0 | K24: =+I24*(1+$C$1) -> 0
E25: =+C25*(1+$C$1) -> 0 | G25: =+E25*(1+$C$1) -> 0 | I25: =+G25*(1+$C$1) -> 0 | K25: =+I25*(1+$C$1) -> 0
A29: Total | B29: =SUM(B20:B28) -> 0 | C29: =+B20*C20+B21*C21+B22*C22+B23*C23+B24*C24+B25*C25+B26*C26+B27*C27+B28*C28 -> 0 | D29: =SUM(D20:D28) -> 3 | E29: =+D20*E20+D21*E21+D22*E22+D23*E23+D24*E24+D25*E25+D26*E26+D27*E27+D28*E28 -> 380.26 | F29: =SUM(F20:F28) -> 4 | G29: =+F20*G20+F21*G21+F22*G22+F23*G23+F24*G24+F25*G25+F26*G26+F27*G27+F28*G28 -> 399.27 | H29: =SUM(H20:H28) -> 4 | I29: =+H20*I20+H21*I21+H22*I22+H23*I23+H24*I24+H25*I25+H26*I26+H27*I27+H28*I28 -> 419.23 | J29: =SUM(J20:J28) -> 4 | K29: =+J20*K20+J21*K21+J22*K22+J23*K23+J24*K24+J25*K25+J26*K26+J27*K27+J28*K28 -> 440.19
A30: Total anual | C30: =C29*12 -> 0 | D30: =E29*12 -> 4563.12 | F30: =G29*12 -> 4791.24 | H30: =I29*12 -> 5030.76 | J30: =K29*12 -> 5282.28
A33: Crecimiento anual | B33: 0.0554
A35: STAFF (Externo) | B35: Año 1 / Mes | D35: Año 2 / Mes | F35: Año 3 / Mes | H35: Año 4 / Mes | J35: Año 5 / Mes
B36: Cant | C36: Salario | D36: Cant | E36: Salario | F36: Cant | G36: Salario | H36: Cant | I36: Salario | J36: Cant | K36: Salario
A37: Contador | B37: 1 | C37: 3650 | E37: =+C37*(1+$B$33) -> 3852.21 | F37: =+D37 -> 0 | G37: =+E37*(1+$B$33) -> 4065.6224 | H37: =+F37 -> 0 | I37: =+G37*(1+$B$33) -> 4290.8579 | J37: =+H37 -> 0 | K37: =+I37*(1+$B$33) -> 4528.5714
G38: =+E38*(1+$B$33) -> 0 | I38: =+G38*(1+$B$33) -> 0 | K38: =+I38*(1+$B$33) -> 0
A39: Total | B39: =SUM(B37:B38) -> 1 | C39: =B37*C37+B38*C38 -> 3650 | D39: =SUM(D37:D38) -> 0 | E39: =+C39*(1+$B$33) -> 3852.21 | F39: =SUM(F37:F38) -> 0 | G39: =+E39*(1+$B$33) -> 4065.6224 | H39: =SUM(H37:H38) -> 0 | I39: =+G39*(1+$B$33) -> 4290.8579 | J39: =SUM(J37:J38) -> 0 | K39: =+I39*(1+$B$33) -> 4528.5714

Sheet Supuestos Ventas y Costos
A1: SUPUESTOS
A3: VENTAS
B4: Año 1 | E4: Año 2 | H4: Año 3 | K4: Año 4 | N4: Año 5
A5: Línea de productos | B5: Unidades | C5: Precio unit | D5: Total | E5: Unidades | F5: Precio unitario | G5: Total | H5: Unidades | I5: Precio unitario | J5: Total | K5: Unidades | L5: Precio unitario | M5: Total | N5: Unidades | O5: Precio unitario | P5: Total
A6: Suscripción Mensual | B6: 325 | C6: 733.48 | D6: =B6*C6 -> 238381 | E6: 652 | F6: =+C6*(1+$F$14) -> 733.48 | G6: =E6*F6 -> 478228.96 | H6: 754 | I6: =+F6*(1+$F$14) -> 733.48 | J6: =H6*I6 -> 553043.92 | K6: 869 | L6: =+I6*(1+$F$14) -> 733.48 | M6: =K6*L6 -> 637394.12 | N6: 1002 | O6: =+L6*(1+$F$14) -> 733.48 | P6: =N6*O6 -> 734946.96
D7: =B7*C7 -> 0 | E7: =+B7*(1+$F$13) -> 0 | F7: =+C7*(1+$F$14) -> 0 | G7: =E7*F7 -> 0 | H7: =+E7*(1+$I$13) -> 0 | I7: =+F7*(1+$I$14) -> 0 | J7: =H7*I7 -> 0 | K7: =+H7*(1+$L$13) -> 0 | L7: =+I7*(1+$L$14) -> 0 | M7: =K7*L7 -> 0 | N7: =+K7*(1+$O$13) -> 0 | O7: =+L7*(1+$O$14) -> 0 | P7: =N7*O7 -> 0
D8: =B8*C8 -> 0 | E8: =+B8*(1+$F$13) -> 0 | F8: =+C8*(1+$F$14) -> 0 | G8: =E8*F8 -> 0 | H8: =+E8*(1+$I$13) -> 0 | I8: =+F8*(1+$I$14) -> 0 | J8: =H8*I8 -> 0 | K8: =+H8*(1+$L$13) -> 0 | L8: =+I8*(1+$L$14) -> 0 | M8: =K8*L8 -> 0 | N8: =+K8*(1+$O$13) -> 0 | O8: =+L8*(1+$O$14) -> 0 | P8: =N8*O8 -> 0
D9: =B9*C9 -> 0 | E9: =B9*(1+$F$13) -> 0 | F9: =+C9*(1+$F$14) -> 0 | G9: =E9*F9 -> 0 | H9: =E9*(1+F13) -> 0 | I9: =+F9*(1+$I$14) -> 0 | J9: =H9*I9 -> 0 | K9: =H9*(1+$L$13) -> 0 | L9: =+I9*(1+$L$14) -> 0 | M9: =K9*L9 -> 0 | N9: =K9*(1+$O$13) -> 0 | O9: =+L9*(1+$O$14) -> 0 | P9: =N9*O9 -> 0
D10: =B10*C10 -> 0 | E10: =+B10*(1+$F$13) -> 0 | F10: =+C10*(1+$F$14) -> 0 | G10: =E10*F10 -> 0 | H10: =+E10*(1+$I$13) -> 0 | I10: =+F10*(1+$I$14) -> 0 | J10: =H10*I10 -> 0 | K10: =+H10*(1+$L$13) -> 0 | L10: =+I10*(1+$L$14) -> 0 | M10: =K10*L10 -> 0 | N10: =+K10*(1+$O$13) -> 0 | O10: =+L10*(1+$O$14) -> 0 | P10: =N10*O10 -> 0
D11: =B11*C11 -> 0 | E11: =+B11*(1+$F$13) -> 0 | F11: =+C11*(1+$F$14) -> 0 | G11: =E11*F11 -> 0 | H11: =+E11*(1+$I$13) -> 0 | I11: =+F11*(1+$I$14) -> 0 | J11: =H11*I11 -> 0 | K11: =+H11*(1+$L$13) -> 0 | L11: =+I11*(1+$L$14) -> 0 | M11: =K11*L11 -> 0 | N11: =+K11*(1+$O$13) -> 0 | O11: =+L11*(1+$O$14) -> 0 | P11: =N11*O11 -> 0
A12: Total | D12: =SUM(D6:D11) -> 238381 | E12: =SUM(E6:E11) -> 652 | G12: =SUM(G6:G11) -> 478228.96 | H12: =SUM(H6:H11) -> 754 | J12: =SUM(J6:J11) -> 553043.92 | K12: =SUM(K6:K11) -> 869 | L12: =+I12*(1+$L$14) -> 0 | M12: =SUM(M6:M11) -> 637394.12 | N12: =SUM(N6:N11) -> 1002 | O12: =+L12*(1+$O$14) -> 0 | P12: =SUM(P6:P11) -> 734946.96
E13: Crec. Unid.: | F13: 0 | H13: Crec. Unid.: | I13: =+F13 -> 0 | K13: Crec. Unid.: | L13: =+F13 -> 0 | N13: Crec. Unid.: | O13: =+F13 -> 0
E14: Crec. Precio: | F14: 0 | H14: Crec. Precio: | I14: =+F14 -> 0 | K14: Crec. Precio: | L14: =+I14 -> 0 | N14: Crec. Precio: | O14: =+F14 -> 0
A17: DETALLE COSTO BRUTO POR PRODUCCIÓN AL MES
B18: =A6 -> Suscripción Mensual | D18: =A7 -> 0 | F18: =+A8 -> 0 | H18: =A9 -> 0 | J18: =+A10 -> 0 | L18: zapatos
B19: Costo | D19: Costo | F19: Costo | H19: Costo | J19: Costo | L19: Costo
A20: Materia prima | B20: 1467.69 | D20: 25 | F20: 30 | H20: 12 | J20: 50 | L20: 80
F21: 0 | H21: 0 | J21: 0 | L21: 0
A22: Total | B22: =SUM(B20:B21) -> 1467.69 | D22: =SUM(D20:D21) -> 25 | F22: =SUM(F20:F21) -> 30 | H22: =SUM(H20:H21) -> 12 | J22: =SUM(J20:J21) -> 50 | L22: =SUM(L20:L21) -> 80
A25: Porcentaje de Incremento Anual Estimado | C25: 0.0662
A27: COSTO BRUTO
B28: Año 1 | E28: Año 2 | H28: Año 3 | K28: Año 4 | N28: Año 5
A29: Líneas de productos | B29: Unidades | C29: Costo unitario | D29: Total | E29: Unidades | F29: Costo unitario | G29: Total | H29: Unidades | I29: Costo unitario | J29: Total | K29: Unidades | L29: Costo unitario | M29: Total | N29: Unidades | O29: Costo unitario | P29: Total
A30: =A6 -> Suscripción Mensual | B30: =B6 -> 325 | C30: =+B22 -> 1467.69 | D30: =B30*C30 -> 476999.25 | E30: =E6 -> 652 | F30: =C30*(1+$C$25) -> 1564.8511 | G30: =E30*F30 -> 1020282.9 | H30: =H6 -> 754 | I30: =F30*(1+$C$25) -> 1668.4442 | J30: =H30*I30 -> 1258006.9 | K30: =K6 -> 869 | L30: =I30*(1+$C$25) -> 1778.8952 | M30: =K30*L30 -> 1545860 | N30: =N6 -> 1002 | O30: =L30*(1+$C$25) -> 1896.6581 | P30: =N30*O30 -> 1900451.4
A31: =A7 -> 0 | B31: =B7 -> 0 | C31: =+D22 -> 25 | D31: =B31*C31 -> 0 | E31: =E7 -> 0 | F31: =C31*(1+$C$25) -> 26.655 | G31: =E31*F31 -> 0 | H31: =H7 -> 0 | I31: =F31*(1+$C$25) -> 28.419561 | J31: =H31*I31 -> 0 | K31: =K7 -> 0 | L31: =I31*(1+$C$25) -> 30.300936 | M31: =K31*L31 -> 0 | N31: =N7 -> 0 | O31: =L31*(1+$C$25) -> 32.306858 | P31: =N31*O31 -> 0
A32: =A8 -> 0 | B32: =B8 -> 0 | C32: =+F22 -> 30 | D32: =B32*C32 -> 0 | E32: =E8 -> 0 | F32: =C32*(1+$C$25) -> 31.986 | G32: =E32*F32 -> 0 | H32: =H8 -> 0 | I32: =F32*(1+$C$25) -> 34.103473 | J32: =H32*I32 -> 0 | K32: =K8 -> 0 | L32: =I32*(1+$C$25) -> 36.361123 | M32: =K32*L32 -> 0 | N32: =N8 -> 0 | O32: =L32*(1+$C$25) -> 38.768229 | P32: =N32*O32 -> 0
A33: =A9 -> 0 | B33: =B9 -> 0 | C33: =H22 -> 12 | D33: =B33*C33 -> 0 | E33: =E9 -> 0 | F33: =C33*(1+$C$25) -> 12.7944 | G33: =E33*F33 -> 0 | H33: =H9 -> 0 | I33: =F33*(1+$C$25) -> 13.641389 | J33: =H33*I33 -> 0 | K33: =K9 -> 0 | L33: =I33*(1+$C$25) -> 14.544449 | M33: =K33*L33 -> 0 | N33: =N9 -> 0 | O33: =L33*(1+$C$25) -> 15.507292 | P33: =N33*O33 -> 0
A34: =A10 -> 0 | B34: =B10 -> 0 | C34: 50 | D34: =B34*C34 -> 0 | E34: =E10 -> 0 | F34: =C34*(1+$C$25) -> 53.31 | G34: =E34*F34 -> 0 | H34: =H10 -> 0 | I34: =F34*(1+$C$25) -> 56.839122 | J34: =H34*I34 -> 0 | K34: =K10 -> 0 | L34: =I34*(1+$C$25) -> 60.601872 | M34: =K34*L34 -> 0 | N34: =N10 -> 0 | O34: =L34*(1+$C$25) -> 64.613716 | P34: =N34*O34 -> 0
A35: =A11 -> 0 | B35: =B11 -> 0 | C35: 80 | D35: =B35*C35 -> 0 | E35: =E11 -> 0 | F35: =C35*(1+$C$25) -> 85.296 | G35: =E35*F35 -> 0 | H35: =H11 -> 0 | I35: =F35*(1+$C$25) -> 90.942595 | J35: =H35*I35 -> 0 | K35: =K11 -> 0 | L35: =I35*(1+$C$25) -> 96.962995 | M35: =K35*L35 -> 0 | N35: =N11 -> 0 | O35: =L35*(1+$C$25) -> 103.38195 | P35: =N35*O35 -> 0
A36: Total | B36: =SUM(B30:B35) -> 325 | D36: =SUM(D30:D35) -> 476999.25 | E36: =SUM(E30:E35) -> 652 | G36: =SUM(G30:G35) -> 1020282.9 | H36: =SUM(H30:H35) -> 754 | J36: =SUM(J30:J35) -> 1258006.9 | K36: =SUM(K30:K35) -> 869 | M36: =SUM(M30:M35) -> 1545860 | N36: =SUM(N30:N35) -> 1002 | P36: =SUM(P30:P35) -> 1900451.4
A40: Detalle del costo del personal con las prestaciones sociales M.O.D.
A41: Costo personal | B41: Año 1 | C41: Año 2 | D41: Año 3 | E41: Año 4 | F41: Año 5
A43: Empleados | B43: =Salarios!B13 -> 1 | C43: =Salarios!D13 -> 2 | D43: =Salarios!F13 -> 2 | E43: =Salarios!H13 -> 2 | F43: =Salarios!J13 -> 2
A44: Salarios | B44: =Salarios!C13*12 -> 180000 | C44: =Salarios!E13*12 -> 190800 | D44: =Salarios!G13*12 -> 202248 | E44: =Salarios!I13*12 -> 214382.88 | F44: =Salarios!K13*12 -> 227245.85
A45: Prestaciones + seguridad social | B45: =B44*0.45 -> 81000 | C45: =C44*0.45 -> 85860 | D45: =D44*0.45 -> 91011.6 | E45: =E44*0.45 -> 96472.296 | F45: =F44*0.45 -> 102260.63
A46: Total costo personal | B46: =B44+B45 -> 261000 | C46: =C44+C45 -> 276660 | D46: =D44+D45 -> 293259.6 | E46: =E44+E45 -> 310855.18 | F46: =F44+F45 -> 329506.49
A47: Prestaciones y Regimen Social están calculadas como un 45% sobre el salario de empleados (1 inss, 8.33 por tres (aguinaldo,vacaciones, indemnizacion), 2 inatec)
A49: Detalle del costo del personal con las prestaciones sociales M.O.I.
A50: Costo personal | B50: Año 1 | C50: Año 2 | D50: Año 3 | E50: Año 4 | F50: Año 5
A52: Empleados | B52: =Salarios!B29 -> 0 | C52: =Salarios!D29 -> 3 | D52: =Salarios!F29 -> 4 | E52: =Salarios!H29 -> 4 | F52: =Salarios!J29 -> 4
...

Sheet Supuestos de Inversión
A2: Concepto | B2: Inversión total | C2: Financiamiento | F2: Tabla de amortización de préstamo | N2: Cálculo Cuota Préstamo
B3: Monto | C3: Fondos Propios | D3: Préstamos | F3: Período | G3: Cuota | H3: Interés | I3: Capital | J3: Saldo | N3: Monto | O3: =+J4 -> 0
A4: Activos intangibles | B4: =SUM(B5:B6) -> 13979.74 | C4: =+SUM(C5:C6) -> 13979.74 | F4: 0 | J4: =B26 -> 0 | N4: Interés Anual | O4: 0.15
A5: Dominio web (.com / .ni) | B5: 550.38 | C5: 550.38 | F5: Año 1 | N5: Plazo en Meses | O5: 36
A6: Registro de propiedad intelectual (MIFIC) | B6: 13429.36 | C6: 13429.36 | F6: 1 | G6: =$B$29*-1 -> 0 | H6: =J4*($B$27/12) -> 0 | I6: =G6-H6 -> 0 | J6: =J4-I6 -> 0 | N6: Cuota | O6: -174.2
F7: 2 | G7: =$B$29*-1 -> 0 | H7: =J6*($B$27/12) -> 0 | I7: =G7-H7 -> 0 | J7: =J6-I7 -> 0 | N7: Seguros | O7: 0
A8: Activos tangibles | B8: =SUM(B9:B10) -> 29353.79 | C8: =+SUM(C9:C10) -> 29353.79 | D8: =+SUM(D9:D11) -> 0 | F8: 3 | G8: =$B$29*-1 -> 0 | H8: =J7*($B$27/12) -> 0 | I8: =G8-H8 -> 0 | J8: =J7-I8 -> 0 | N8: Cuota Total | O8: 174.2
A9: Laptop | B9: 18346.12 | C9: =B9 -> 18346.12 | F9: 4 | G9: =$B$29*-1 -> 0 | H9: =J8*($B$27/12) -> 0 | I9: =G9-H9 -> 0 | J9: =J8-I9 -> 0
A10: Dispositivos de Prueba (Tableta/Smartphone) | B10: 11007.67 | C10: 11007.67 | F10: 5 | G10: =$B$29*-1 -> 0 | H10: =J9*($B$27/12) -> 0 | I10: =G10-H10 -> 0 | J10: =J9-I10 -> 0
F11: 6 | G11: =$B$29*-1 -> 0 | H11: =J10*($B$27/12) -> 0 | I11: =G11-H11 -> 0 | J11: =J10-I11 -> 0
F12: 7 | G12: =$B$29*-1 -> 0 | H12: =J10*($B$27/12) -> 0 | I12: =G12-H12 -> 0 | J12: =J11-I12 -> 0
A13: Capital de Trabajo: | B13: =B14 -> 66484.739 | C13: =+B13 -> 66484.739 | F13: 8 | G13: =$B$29*-1 -> 0 | H13: =J12*($B$27/12) -> 0 | I13: =G13-H13 -> 0 | J13: =J12-I13 -> 0
A14: Capital Trabajo | B14: =+(EFINANCIEROS!C5+EFINANCIEROS!C7+EFINANCIEROS!C8)/12 -> 66484.739 | C14: =+B14 -> 66484.739 | F14: 9 | G14: =$B$29*-1 -> 0 | H14: =J13*($B$27/12) -> 0 | I14: =G14-H14 -> 0 | J14: =J13-I14 -> 0
F15: 10 | G15: =$B$29*-1 -> 0 | H15: =J14*($B$27/12) -> 0 | I15: =G15-H15 -> 0 | J15: =J14-I15 -> 0 | K15: AÑO 1
A16: Gastos pre operativos | B16: =B17 -> 1500 | C16: =+B16 -> 1500 | F16: 11 | G16: =$B$29*-1 -> 0 | H16: =J15*($B$27/12) -> 0 | I16: =G16-H16 -> 0 | J16: =J15-I16 -> 0 | K16: Interés | L16: Capital
A17: Gastos pre operativos | B17: 1500 | C17: =+B17 -> 1500 | F17: 12 | G17: =$B$29*-1 -> 0 | H17: =J16*($B$27/12) -> 0 | I17: =G17-H17 -> 0 | J17: =J16-I17 -> 0 | K17: =SUM(H6:H17) -> 0 | L17: =SUM(I6:I17) -> 0
F18: Año 2
A19: Totales: | B19: =B16+B8+B13+B4 -> 111318.27 | C19: =C16+C13+C4+C8 -> 111318.27 | D19: =D8+D4 -> 0 | F19: 13 | G19: =$B$29*-1 -> 0 | H19: =J17*($B$27/12) -> 0 | I19: =G19-H19 -> 0 | J19: =J17-I19 -> 0
B20: Total | C20: Aporte | D20: Financiamiento | F20: 14 | G20: =$B$29*-1 -> 0 | H20: =J19*($B$27/12) -> 0 | I20: =G20-H20 -> 0 | J20: =J19-I20 -> 0
B21: =SUM(C21:D21) -> 1 | C21: =+(C19/B19) -> 1 | D21: =+(D19/B19) -> 0 | F21: 15 | G21: =$B$29*-1 -> 0 | H21: =J20*($B$27/12) -> 0 | I21: =G21-H21 -> 0 | J21: =J20-I21 -> 0
F22: 16 | G22: =$B$29*-1 -> 0 | H22: =J21*($B$27/12) -> 0 | I22: =G22-H22 -> 0 | J22: =J21-I22 -> 0
F23: 17 | G23: =$B$29*-1 -> 0 | H23: =J22*($B$27/12) -> 0 | I23: =G23-H23 -> 0 | J23: =J22-I23 -> 0
F24: 18 | G24: =$B$29*-1 -> 0 | H24: =J23*($B$27/12) -> 0 | I24: =G24-H24 -> 0 | J24: =J23-I24 -> 0
A25: Cálculo Cuota Préstamo | F25: 19 | G25: =$B$29*-1 -> 0 | H25: =J24*($B$27/12) -> 0 | I25: =G25-H25 -> 0 | J25: =J24-I25 -> 0
A26: Monto | B26: =D19 -> 0 | F26: 20 | G26: =$B$29*-1 -> 0 | H26: =J25*($B$27/12) -> 0 | I26: =G26-H26 -> 0 | J26: =J25-I26 -> 0
A27: Interés Anual | B27: 0.0938 | F27: 21 | G27: =$B$29*-1 -> 0 | H27: =J26*($B$27/12) -> 0 | I27: =G27-H27 -> 0 | J27: =J26-I27 -> 0
A28: Plazo en Meses | B28: 48 | F28: 22 | G28: =$B$29*-1 -> 0 | H28: =J27*($B$27/12) -> 0 | I28: =G28-H28 -> 0 | J28: =J27-I28 -> 0 | K28: AÑO 2
A29: Cuota | B29: =PMT((B27/12),B28,B26) -> 0 | F29: 23 | G29: =$B$29*-1 -> 0 | H29: =J28*($B$27/12) -> 0 | I29: =G29-H29 -> 0 | J29: =J28-I29 -> 0 | K29: Interés | L29: Capital
A30: Seguros | B30: 0 | F30: 24 | G30: =$B$29*-1 -> 0 | H30: =J29*($B$27/12) -> 0 | I30: =G30-H30 -> 0 | J30: =J29-I30 -> 0 | K30: =SUM(H19:H30) -> 0 | L30: =SUM(I19:I30) -> 0
A31: Cuota Total | B31: =(B29*-1)*(1+B30) -> 0 | F31: Año 3
F32: 25 | G32: =$B$29*-1 -> 0 | H32: =J30*($B$27/12) -> 0 | I32: =G32-H32 -> 0 | J32: =J30-I32 -> 0
F33: 26 | G33: =$B$29*-1 -> 0 | H33: =J32*($B$27/12) -> 0 | I33: =G33-H33 -> 0 | J33: =J32-I33 -> 0
F34: 27 | G34: =$B$29*-1 -> 0 | H34: =J33*($B$27/12) -> 0 | I34: =G34-H34 -> 0 | J34: =J33-I34 -> 0
F35: 28 | G35: =$B$29*-1 -> 0 | H35: =J34*($B$27/12) -> 0 | I35: =G35-H35 -> 0 | J35: =J34-I35 -> 0
F36: 29 | G36: =$B$29*-1 -> 0 | H36: =J35*($B$27/12) -> 0 | I36: =G36-H36 -> 0 | J36: =J35-I36 -> 0
F37: 30 | G37: =$B$29*-1 -> 0 | H37: =J36*($B$27/12) -> 0 | I37: =G37-H37 -> 0 | J37: =J36-I37 -> 0
F38: 31 | G38: =$B$29*-1 -> 0 | H38: =J37*($B$27/12) -> 0 | I38: =G38-H38 -> 0 | J38: =J37-I38 -> 0
F39: 32 | G39: =$B$29*-1 -> 0 | H39: =J38*($B$27/12) -> 0 | I39: =G39-H39 -> 0 | J39: =J38-I39 -> 0
F40: 33 | G40: =$B$29*-1 -> 0 | H40: =J39*($B$27/12) -> 0 | I40: =G40-H40 -> 0 | J40: =J39-I40 -> 0
F41: 34 | G41: =$B$29*-1 -> 0 | H41: =J40*($B$27/12) -> 0 | I41: =G41-H41 -> 0 | J41: =J40-I41 -> 0 | K41: AÑO 3
...

Sheet EFINANCIEROS
A2: Calculo de Rentabilidad Proyectada
C3: Año 1 | D3: Año 2 | E3: Año 3 | F3: Año 4 | G3: Año 5
A4: Ventas | C4: ='Supuestos Ventas y Costos'!D12 -> 238381 | D4: ='Supuestos Ventas y Costos'!G12 -> 478228.96 | E4: ='Supuestos Ventas y Costos'!J12 -> 553043.92 | F4: ='Supuestos Ventas y Costos'!M12 -> 637394.12 | G4: ='Supuestos Ventas y Costos'!P12 -> 734946.96
A5: Costo de los bienes vendidos | C5: ='Supuestos Ventas y Costos'!D36+'Supuestos Ventas y Costos'!B46 -> 737999.25 | D5: ='Supuestos Ventas y Costos'!G36+'Supuestos Ventas y Costos'!C46 -> 1296942.9 | E5: ='Supuestos Ventas y Costos'!J36+'Supuestos Ventas y Costos'!D46 -> 1551266.5 | F5: ='Supuestos Ventas y Costos'!M36+'Supuestos Ventas y Costos'!E46 -> 1856715.1 | G5: ='Supuestos Ventas y Costos'!P36+'Supuestos Ventas y Costos'!F46 -> 2229957.9
A6: Utilidad Bruta | C6: =C4-C5 -> -499618.25 | D6: =D4-D5 -> -818713.94 | E6: =E4-E5 -> -998222.62 | F6: =F4-F5 -> -1219321 | G6: =G4-G5 -> -1495010.9
A7: Gastos Generales (sin depreciación) | C7: ='Supuestos Ventas y Costos'!B60 -> 16017.62 | D7: ='Supuestos Ventas y Costos'!C60 -> 23081.627 | E7: ='Supuestos Ventas y Costos'!D60 -> 26372.618 | F7: ='Supuestos Ventas y Costos'!E60 -> 30135.206 | G7: ='Supuestos Ventas y Costos'!F60 -> 34473.851
A8: Gastos Administración | C8: ='Supuestos Ventas y Costos'!B61 -> 43800 | D8: ='Supuestos Ventas y Costos'!C61 -> 52843.044 | E8: ='Supuestos Ventas y Costos'!D61 -> 55734.767 | F8: ='Supuestos Ventas y Costos'!E61 -> 58784.897 | G8: ='Supuestos Ventas y Costos'!F61 -> 62002.163
A9: Depreciación | C9: ='Supuestos Ventas y Costos'!B67 -> 0 | D9: ='Supuestos Ventas y Costos'!C67 -> 0 | E9: ='Supuestos Ventas y Costos'!D67 -> 0 | F9: ='Supuestos Ventas y Costos'!E67 -> 0 | G9: ='Supuestos Ventas y Costos'!F67 -> 0
A10: Amortización Gastos Preoperativos | C10: =+BALANCES!C33 -> 300 | D10: =+C10 -> 300 | E10: =+D10 -> 300 | F10: =+E10 -> 300 | G10: =+F10 -> 300
A11: Total Gastos de Operación | C11: =SUM(C7:C10) -> 60117.62 | D11: =SUM(D7:D10) -> 76224.671 | E11: =SUM(E7:E10) -> 82407.385 | F11: =SUM(F7:F10) -> 89220.103 | G11: =SUM(G7:G10) -> 96776.014
A13: Utilidad de Operación | C13: =+C6-C11 -> -559735.87 | D13: =+D6-D11 -> -894938.61 | E13: =+E6-E11 -> -1080630 | F13: =+F6-F11 -> -1308541.1 | G13: =+G6-G11 -> -1591786.9
A14: Intereses pagados | C14: ='Supuestos de Inversión'!K17 -> 0 | D14: ='Supuestos de Inversión'!K30 -> 0 | E14: ='Supuestos de Inversión'!K43 -> 0 | F14: ='Supuestos de Inversión'!K56 -> 0
A15: Utilidad antes de impuestos | C15: =C13-C14 -> -559735.87 | D15: =D13-D14 -> -894938.61 | E15: =E13-E14 -> -1080630 | F15: =F13-F14 -> -1308541.1 | G15: =G13-G14 -> -1591786.9
A16: Impuestos 30% IR | C16: =C15*30% -> -167920.76 | D16: =D15*30% -> -268481.58 | E16: =E15*30% -> -324189 | F16: =F15*30% -> -392562.33 | G16: =G15*30% -> -477536.08
A17: Utilidad neta | C17: =C15-C16 -> -391815.11 | D17: =D15-D16 -> -626457.03 | E17: =E15-E16 -> -756441 | F17: =F15-F16 -> -915978.78 | G17: =G15-G16 -> -1114250.9
A21: Flujo de fondos
B22: AÑO 0 | C22: AÑO 1 | D22: AÑO 2 | E22: AÑO 3 | F22: AÑO 4 | G22: AÑO 5
A23: Utilidad contable | C23: =C17 -> -391815.11 | D23: =D17 -> -626457.03 | E23: =E17 -> -756441 | F23: =F17 -> -915978.78 | G23: =G17 -> -1114250.9
A24: Depreciación | C24: =C9 -> 0 | D24: =D9 -> 0 | E24: =E9 -> 0 | F24: =F9 -> 0 | G24: =G9 -> 0
A25: Amortización | C25: ='Supuestos de Inversión'!L17 -> 0 | D25: ='Supuestos de Inversión'!L30 -> 0 | E25: ='Supuestos de Inversión'!L43 -> 0 | F25: ='Supuestos de Inversión'!L56 -> 0
A26: Flujo de fondos | B26: =-'Supuestos de Inversión'!B19 -> -111318.27 | C26: =C23+C24-C25 -> -391815.11 | D26: =D23+D24-D25 -> -626457.03 | E26: =E23+E24-E25 -> -756441 | F26: =F23+F24-F25 -> -915978.78 | G26: =G23+G24-G25 -> -1114250.9
A27: VAN al 18% | B27: {=NPV(0.18,C26:G26)+B26} -> -2313171
A28: TIR | B28: =IRR(B26:G26) -> #NUM!
A29: Tasa de descuento | B29: 0.18
C30: FACTOR DE DESCUENTO
C31: Año 1 | D31: AÑO 2 | E31: AÑO 3 | F31: AÑO 4 | G31: AÑO 5
C32: =1+B29 -> 1.18 | D32: =C32*$C$32 -> 1.3924 | E32: =D32*$C$32 -> 1.643032 | F32: =E32*$C$32 -> 1.9387778 | G32: =F32*$C$32 -> 2.2877578
C33: FLUJO DE FONDOS DESCONTADOS POR AÑO
C34: 1 | D34: 2 | E34: 3 | F34: 4 | G34: 5
A35: RELACION BENEFICIO COSTO | B35: =SUM(C35:G35)/-B26 -> -19.779797 | C35: =C26/C32 -> -332046.7 | D35: =D26/D32 -> -449911.68 | E35: =E26/E32 -> -460393.35 | F35: =F26/F32 -> -472451.66 | G35: =G26/G32 -> -487049.32
A36: Periodo de Recuperacion | C36: =B26+C35 -> -443364.97 | D36: =D35+C36 -> -893276.66 | E36: =E35+D36 -> -1353670 | F36: =F35+E36 -> -1826121.7 | G36: =G35+F36 -> -2313171
A39: Razones Financieras
B40: AÑO 1 | C40: AÑO 2 | D40: AÑO 3 | E40: AÑO 4 | F40: AÑO 5
A41: Rentabilidad sobre ventas | B41: =C17/C4 -> -1.6436507 | C41: =D17/D4 -> -1.3099521 | D41: =E17/E4 -> -1.3677775 | E41: =F17/F4 -> -1.4370681 | F41: =G17/G4 -> -1.516097
A42: Rentabilidad sobre inversion | B42: =C17/-$B$26 -> -3.5197736 | C42: =D17/-$B$26 -> -5.627621 | D42: =E17/-$B$26 -> -6.7952997 | E42: =F17/-$B$26 -> -8.2284677 | F42: =G17/-$B$26 -> -10.009596
A46: Punto de equilibrio (U$)
A47: Detalle | C47: Año 1 | D47: Año 2 | E47: Año 3 | F47: Año 4 | G47: Año 5
A48: Porcentaje sobre ventas % | C48: =C49/C4 -> -0.64075928 | D48: =D49/D4 -> -0.15515631 | E48: =E49/E4 -> -0.072596692 | F48: =F49/F4 -> -0.0079396994 | G48: =G49/G4 -> 0.04423285
A49: Punto de Equilibrio | C49: =(C53/(1-(C61/C50))) -> -152744.84 | D49: =(D53/(1-(D61/D50))) -> -74200.239 | E49: =(E53/(1-(E61/E50))) -> -40149.159 | F49: =(F53/(1-(F61/F50))) -> -5060.7177 | G49: =(G53/(1-(G61/G50))) -> 32508.799
A50: Ventas | C50: =C4 -> 238381 | D50: =D4 -> 478228.96 | E50: =E4 -> 553043.92 | F50: =F4 -> 637394.12 | G50: =G4 -> 734946.96
...

Sheet BALANCES
A2: Balance general
A3: ACTIVOS | B3: AÑO 0 | C3: AÑO 1 | D3: AÑO 2 | E3: AÑO 3 | F3: AÑO 4 | G3: AÑO 5
A4: Activos circulantes | B4: =SUM(B5) -> 66484.739 | C4: =SUM(C5) -> -325330.37 | D4: =SUM(D5) -> -951787.4 | E4: =SUM(E5) -> -1708228.4 | F4: =SUM(F5) -> -2624207.2 | G4: =SUM(G5) -> -3738458
A5: Caja y bancos | B5: =EFINANCIEROS!B74 -> 66484.739 | C5: =EFINANCIEROS!C74 -> -325330.37 | D5: =EFINANCIEROS!D74 -> -951787.4 | E5: =EFINANCIEROS!E74 -> -1708228.4 | F5: =EFINANCIEROS!F74 -> -2624207.2 | G5: =EFINANCIEROS!G74 -> -3738458
A6: Activo fijo | B6: =SUM(B7:B10) -> 43333.53 | C6: =SUM(C7:C10) -> 43333.53 | D6: =SUM(D7:D10) -> 43333.53 | E6: =SUM(E7:E10) -> 43333.53 | F6: =SUM(F7:F10) -> 43333.53 | G6: =SUM(G7:G10) -> 43333.53
A7: Equipo de Oficina | B7: =+'Supuestos de Inversión'!B9 -> 18346.12 | C7: =B7 -> 18346.12 | D7: =C7 -> 18346.12 | E7: =D7 -> 18346.12 | F7: =E7 -> 18346.12 | G7: =F7 -> 18346.12
A8: Terreno y Edificio | B8: =+'Supuestos de Inversión'!B4 -> 13979.74 | C8: =B8 -> 13979.74 | D8: =C8 -> 13979.74 | E8: =D8 -> 13979.74 | F8: =E8 -> 13979.74 | G8: =F8 -> 13979.74
A9: Otros Equipos y Utensilios | B9: =+'Supuestos de Inversión'!B10 -> 11007.67 | C9: =B9 -> 11007.67 | D9: =C9 -> 11007.67 | E9: =D9 -> 11007.67 | F9: =E9 -> 11007.67 | G9: =F9 -> 11007.67
A10: Depreciación acumulada | C10: =-EFINANCIEROS!C24 -> 0 | D10: =C10-EFINANCIEROS!D24 -> 0 | E10: =D10-EFINANCIEROS!E24 -> 0 | F10: =E10-EFINANCIEROS!F24 -> 0 | G10: =F10-EFINANCIEROS!G24 -> 0
A11: Activo Diferido | B11: =+'Supuestos de Inversión'!B17 -> 1500 | C11: =+'Supuestos de Inversión'!C17 -> 1500 | D11: =+C11 -> 1500 | E11: =+D11 -> 1500 | F11: =+E11 -> 1500 | G11: =+F11 -> 1500
A12: Pre-Operativos (Constitución y Legalización) | B12: =+B11 -> 1500 | C12: 0 | D12: =+D11 -> 1500 | E12: =+E11 -> 1500 | F12: =+F11 -> 1500 | G12: =+G11 -> 1500
A13: Amortización Diferidos | C13: =+C33 -> 300 | D13: =+C13+C13 -> 600 | E13: =+D13+C13 -> 900 | F13: =+E13+C13 -> 1200 | G13: =+F13+C13 -> 1500
A14: Total de activos diferidos | B14: =B11-B12 -> 0 | C14: =+C11-C13 -> 1200 | D14: =+D11-D13 -> 900 | E14: =+E11-E13 -> 600 | F14: =+F11-F13 -> 300 | G14: =+G11-G13 -> 0
A15: Total de activos | B15: =B4+B6+B11 -> 111318.27 | C15: =C4+C6+C11 -> -280496.84 | D15: =D4+D6+D11 -> -906953.87 | E15: =E4+E6+E11 -> -1663394.9 | F15: =F4+F6+F11 -> -2579373.7 | G15: =G4+G6+G11 -> -3693624.5
A17: PASIVOS | B17: =+B18 -> 0 | C17: =+C18 -> 0 | D17: =+D18 -> 0 | E17: =+E18 -> 0 | F17: =+F18 -> 0 | G17: =+G18 -> 0
A18: Pasivo largo plazo | B18: =B19 -> 0 | C18: =C19 -> 0 | D18: =D19 -> 0 | E18: =E19 -> 0 | F18: =F19 -> 0 | G18: =G19 -> 0
A19: Prestamo largo plazo | B19: ='Supuestos de Inversión'!D19 -> 0 | C19: =B19-EFINANCIEROS!C25 -> 0 | D19: =C19-EFINANCIEROS!D25 -> 0 | E19: =D19-EFINANCIEROS!E25 -> 0 | F19: =E19-EFINANCIEROS!F25 -> 0 | G19: =F19-EFINANCIEROS!G25 -> 0
A21: CAPITAL | B21: =SUM(B22:B24) -> 111318.27 | C21: =SUM(C22:C24) -> -280496.84 | D21: =SUM(D22:D24) -> -906953.87 | E21: =SUM(E22:E24) -> -1663394.9 | F21: =SUM(F22:F24) -> -2579373.7 | G21: =SUM(G22:G24) -> -3693624.5
A22: Capital social | B22: =+'Supuestos de Inversión'!C19 -> 111318.27 | C22: =B22 -> 111318.27 | D22: =C22 -> 111318.27 | E22: =D22 -> 111318.27 | F22: =E22 -> 111318.27 | G22: =F22 -> 111318.27
A23: Utilidad acumulada | D23: =C24 -> -391815.11 | E23: =D23+D24 -> -1018272.1 | F23: =E23+E24 -> -1774713.1 | G23: =F23+F24 -> -2690691.9
A24: Utilidad del periodo | C24: =EFINANCIEROS!C23 -> -391815.11 | D24: =EFINANCIEROS!D23 -> -626457.03 | E24: =EFINANCIEROS!E23 -> -756441 | F24: =EFINANCIEROS!F23 -> -915978.78 | G24: =EFINANCIEROS!G23 -> -1114250.9
A26: Total pasivo mas capital | B26: =B21+B17 -> 111318.27 | C26: =C21+C17 -> -280496.84 | D26: =D21+D17 -> -906953.87 | E26: =E21+E17 -> -1663394.9 | F26: =F21+F17 -> -2579373.7 | G26: =G21+G17 -> -3693624.5
B28: =B15-B26 -> 0 | C28: =C15-C26 -> 0 | D28: =D15-D26 -> 0 | E28: =E15-E26 -> 0 | F28: =F15-F26 -> 0 | G28: =G15-G26 -> 0
A33: Activo Diferido | B33: =+B11 -> 1500 | C33: =+B33/5 -> 300

Sheet Hoja1
